Workbook

Sheet Связи
A2: Маркеры | B2: Направление - direction (spr_partners)
B3: Менеджер - Ответсвенный для прогноза (b_crm_deal)
B4: План - Потенциал сумма (b_crm_deal)
B5: Факт - Amount (doc_Sales)
B6: Даты - Date (doc_Sales)
A9: Связи | B9: b_crm_deal - ID
B10: b_uts_crm_deal - VALUE
B12: b_uts_crm_deal - № ЗК
B13: doc_OrderSales- Number
B15: doc_OrderSales- id 1c
B16: doc_Sales - Zakaz_id_1c
B18: doc_OrderSales- Partner id
B19: spr_partners - id_1c

Sheet b_crm_deal
A1: ID | B1: TITLE | C1: ASSIGNED_BY_ID | D1: DATE_CREATE | E1: Группа стадий | F1: Стадия крупно | G1: b_crm_deal_category.NAME.1 | H1: b_crm_status.NAME | I1: Потенциал дата | J1: b_crm_company.TITLE | K1: b_crm_company.Ответственный за клиента | L1: b_crm_deal_category.NAME | M1: LAST_ACTIVITY_TIME | N1: MOVED_TIME | O1: Для проверки | P1: Ответственный | Q1: Потенциал с конверсией | R1: Потенциал сумма | S1: b_crm_company.ID | T1: COMPANY_ID | U1: Прогноз март 2026 | V1: Прогноз апрель 2026 | W1: Сумма с согласовании заказа | X1: Сумма в производстве | Y1: Сумма отгружено | Z1: Сумма в КП | AA1: Срок перехода | AB1: Просрочка | AC1: Ссылка | AD1: Год | AE1: Стандарт/Проект | AF1: Ответсвенный для прогноза
A2: 57250 | B2: Жилой комплекс "Курский" | C2: 110 | D2: 45734.458 | E2: Активные продажи | F2: Лидогенерация | G2: Строительство | H2: Новая сделка | I2: 45991 | J2: null | K2: null | L2: Строительство | M2: 45734.458 | N2: 45734.458 | O2: OK | P2: Алексеева М.И. | Q2: 500000 | R2: 4000000 | S2: null | T2: null | U2: null | V2: null | W2: null | X2: null | Y2: null | Z2: null | AA2: 3 | AB2: Не просрочена | AC2: https://crm.example.com/deal/57250 | AD2: 2025 | AE2: Проект | AF2: Алексеева М.И.
A3: 57249 | B3: Сибур, Анапа (дозаказ) | C3: 101 | D3: 45734.448 | E3: Активные продажи | F3: Технический | G3: Строительство | H3: Запуск в производство | I3: 45777 | J3: Фасад-Строй | K3: Васильева К.А. | L3: Строительство | M3: 45734.451 | N3: 45734.449 | O3: В производстве | P3: Сергеева Н.В. | Q3: 1200000 | R3: 1200000 | S3: 10001 | T3: 10001 | U3: null | V3: null | W3: null | X3: 1200000 | Y3: null | Z3: null | AA3: 15 | AB3: Не просрочена | AC3: https://crm.example.com/deal/57249 | AD3: 2025 | AE3: Проект | AF3: Сергеева Н.В.
A4: 57248 | B4: Артек (дозаказ) | C4: 101 | D4: 45734.431 | E4: Активные продажи | F4: Технический | G4: Строительство | H4: Запуск в производство | I4: 45779 | J4: СтройКомплект | K4: Каримова Д.Р. | L4: Строительство | M4: 45734.431 | N4: 45734.431 | O4: В производстве | P4: Сергеева Н.В. | Q4: 700000 | R4: 700000 | S4: 10002 | T4: 10002 | U4: null | V4: null | W4: null | X4: 1500000 | Y4: null | Z4: null | AA4: 15 | AB4: Не просрочена | AC4: https://crm.example.com/deal/57248 | AD4: 2025 | AE4: Проект | AF4: Сергеева Н.В.
A5: 57247 | B5: Сибур, Анапа (двери) | C5: 101 | D5: 45734.427 | E5: Активные продажи | F5: Технический | G5: Строительство | H5: Запуск в производство | I5: 45780 | J5: Виртус | K5: Сергеева Н.В. | L5: Строительство | M5: 45734.427 | N5: 45734.428 | O5: В производстве | P5: Сергеева Н.В. | Q5: 650000 | R5: 650000 | S5: 10003 | T5: 10003 | U5: null | V5: null | W5: null | X5: 1300000 | Y5: null | Z5: null | AA5: 15 | AB5: Не просрочена | AC5: https://crm.example.com/deal/57247 | AD5: 2025 | AE5: Проект | AF5: Сергеева Н.В.
A6: 57246 | B6: Стандартные отгрузки "РесторанСервис" | C6: 107 | D6: 45734.417 | E6: Активные продажи | F6: Технический | G6: Строительство | H6: Запуск в производство | I6: 45807 | J6: РесторанСервис | K6: Родина Т.В. | L6: Строительство | M6: 45734.417 | N6: 45734.417 | O6: В производстве | P6: Новикова А.В. | Q6: 3500000 | R6: 3500000 | S6: 10004 | T6: 10004 | U6: null | V6: null | W6: null | X6: 600000 | Y6: null | Z6: null | AA6: 15 | AB6: Не просрочена | AC6: https://crm.example.com/deal/57246 | AD6: 2025 | AE6: Стандарт | AF6: Новикова А.В.
A7: 57245 | B7: HPL панели, г. Москва | C7: 102 | D7: 45734.406 | E7: Активные продажи | F7: Лидогенерация | G7: Строительство | H7: Сбор информации | I7: 45867 | J7: null | K7: null | L7: Строительство | M7: 45734.458 | N7: 45734.41 | O7: OK | P7: Петрова Е.В. | Q7: 0 | R7: 0 | S7: null | T7: null | U7: null | V7: null | W7: null | X7: null | Y7: null | Z7: null | AA7: 3 | AB7: Не просрочена | AC7: https://crm.example.com/deal/57245 | AD7: 2025 | AE7: Проект | AF7: Петрова Е.В.
A8: 57244 | B8: Бизнес-центр "Вперед" | C8: 110 | D8: 45734.396 | E8: Активные продажи | F8: Лидогенерация | G8: Строительство | H8: Проверка объекта | I8: 45838 | J8: Фасад-Строй | K8: Васильева К.А. | L8: Строительство | M8: 45734.458 | N8: 45734.427 | O8: OK | P8: Алексеева М.И. | Q8: 2000000 | R8: 2000000 | S8: 10001 | T8: 10001 | U8: null | V8: null | W8: null | X8: null | Y8: null | Z8: null | AA8: null | AB8: Нет | AC8: https://crm.example.com/deal/57244 | AD8: 2025 | AE8: Проект | AF8: Алексеева М.И.
A9: 57243 | B9: Входящий звонок (дилер) | C9: 112 | D9: 45734.375 | E9: Успешно | F9: Передан дилеру | G9: Передан дилеру | H9: Передан дилеру | I9: null | J9: null | K9: null | L9: Передан дилеру | M9: 45734.375 | N9: 45734.376 | O9: OK | P9: Орлова Т.В. | Q9: 0 | R9: 0 | S9: null | T9: null | U9: null | V9: null | W9: null | X9: null | Y9: null | Z9: null | AA9: null | AB9: Нет | AC9: https://crm.example.com/deal/57243 | AD9: 2025 | AE9: Проект | AF9: null
A10: 57242 | B10: Частный дом, Казахстан | C10: 107 | D10: 45734.354 | E10: Активные продажи | F10: Квалификация | G10: Инжиниринг | H10: В очереди | I10: 45899 | J10: ТОО "Еврофасад" | K10: Новикова А.В. | L10: Инжиниринг | M10: 45734.354 | N10: 45734.358 | O10: OK | P10: Новикова А.В. | Q10: 0 | R10: 0 | S10: 10005 | T10: 10005 | U10: null | V10: null | W10: null | X10: null | Y10: null | Z10: null | AA10: null | AB10: Нет | AC10: https://crm.example.com/deal/57242 | AD10: 2025 | AE10: Проект | AF10: Новикова А.В.
A11: 57241 | B11: РБС Групп (двери) | C11: 104 | D11: 45734.344 | E11: Активные продажи | F11: Технический | G11: Строительство | H11: Выставление счета | I11: 45747 | J11: РБС Групп | K11: Алексеева М.И. | L11: Строительство | M11: 45734.344 | N11: 45734.347 | O11: Подтвержден | P11: Сидоров В.В. | Q11: 500000 | R11: 500000 | S11: 10006 | T11: 10006 | U11: null | V11: null | W11: null | X11: 500000 | Y11: null | Z11: 500000 | AA11: 5 | AB11: Не просрочена | AC11: https://crm.example.com/deal/57241 | AD11: 2025 | AE11: Проект | AF11: Сидоров В.В.
A12: 57240 | B12: Спа-центр "Коприно" | C12: 110 | D12: 45734.333 | E12: Активные продажи | F12: Лидогенерация | G12: Строительство | H12: Проверка объекта | I12: 45870 | J12: СтройКомплект | K12: Сергеева Н.В. | L12: Строительство | M12: 45734.333 | N12: 45734.396 | O12: OK | P12: Алексеева М.И. | Q12: 2000000 | R12: 2000000 | S12: 10007 | T12: 10007 | U12: null | V12: null | W12: null | X12: null | Y12: null | Z12: null | AA12: null | AB12: Нет | AC12: https://crm.example.com/deal/57240 | AD12: 2025 | AE12: Проект | AF12: Алексеева М.И.
A13: 57239 | B13: Стандартные отгрузки "Веста-Краснодар" | C13: 113 | D13: 45734.333 | E13: Активные продажи | F13: Технический | G13: Строительство | H13: Запуск в производство | I13: 45747 | J13: Веста-Краснодар | K13: Сергеева Н.В. | L13: Строительство | M13: 45734.5 | N13: 45734.333 | O13: В производстве | P13: Горин А.Н. | Q13: 50000 | R13: 50000 | S13: 10008 | T13: 10008 | U13: null | V13: null | W13: null | X13: 50000 | Y13: null | Z13: 40000 | AA13: 15 | AB13: Не просрочена | AC13: https://crm.example.com/deal/57239 | AD13: 2025 | AE13: Стандарт | AF13: Горин А.Н.
A14: 57238 | B14: Рентгенозащитные двери | C14: 110 | D14: 45734.323 | E14: Активные продажи | F14: Технический | G14: Строительство | H14: Запуск в производство | I14: 45747 | J14: СтройДизайн | K14: Алексеева М.И. | L14: Строительство | M14: 45734.5 | N14: 45734.326 | O14: В производстве | P14: Алексеева М.И. | Q14: 150000 | R14: 150000 | S14: 10009 | T14: 10009 | U14: null | V14: null | W14: null | X14: 150000 | Y14: null | Z14: null | AA14: 15 | AB14: Не просрочена | AC14: https://crm.example.com/deal/57238 | AD14: 2025 | AE14: Проект | AF14: Алексеева М.И.
A15: 57237 | B15: Откосы для КПП больниц | C15: 108 | D15: 45734.312 | E15: Активные продажи | F15: Технический | G15: Строительство | H15: Согласование отгрузки | I15: 45746 | J15: Алексвит | K15: Васильева К.А. | L15: Строительство | M15: 45734.521 | N15: 45734.319 | O15: Отгружено | P15: Васильева К.А. | Q15: 400000 | R15: 400000 | S15: 10010 | T15: 10010 | U15: null | V15: null | W15: null | X15: 400000 | Y15: null | Z15: 500000 | AA15: 5 | AB15: Не просрочена | AC15: https://crm.example.com/deal/57237 | AD15: 2025 | AE15: Проект | AF15: Васильева К.А.
A16: 57236 | B16: Центр детской онкологии, Беларусь | C16: 107 | D16: 45734.302 | E16: Активные продажи | F16: Технический | G16: Строительство СНГ | H16: Выставление счета | I16: 45807 | J16: Тисса | K16: Родина Т.В. | L16: Строительство СНГ | M16: 45734.302 | N16: 45734.312 | O16: Подтвержден | P16: Новикова А.В. | Q16: 800000 | R16: 800000 | S16: 10011 | T16: 10011 | U16: null | V16: null | W16: 800000 | X16: null | Y16: null | Z16: null | AA16: 5 | AB16: Не просрочена | AC16: https://crm.example.com/deal/57236 | AD16: 2025 | AE16: Проект | AF16: Новикова А.В.
A17: 57235 | B17: Мебель для библиотеки Орска | C17: 104 | D17: 45734.285 | E17: Активные продажи | F17: Лидогенерация | G17: Строительство | H17: Сбор информации | I17: null | J17: ЦБС Орска | K17: Козлов Д.Д. | L17: Строительство | M17: 45734.288 | N17: 45734.292 | O17: OK | P17: Сидоров В.В. | Q17: 0 | R17: 0 | S17: 10012 | T17: 10012 | U17: null | V17: null | W17: null | X17: null | Y17: null | Z17: null | AA17: 3 | AB17: Не просрочена | AC17: https://crm.example.com/deal/57235 | AD17: 2025 | AE17: Проект | AF17: Сидоров В.В.
A18: 57234 | B18: Аналитприбор, заказ 882 | C18: 106 | D18: 45733.688 | E18: Активные продажи | F18: Технический | G18: Логистика | H18: Выставление счета | I18: 45784 | J18: Аналитприбор | K18: Соколова И.М. | L18: Логистика | M18: 45734.333 | N18: 45733.688 | O18: Подтвержден | P18: Соколова И.М. | Q18: 1500000 | R18: 2000000 | S18: 10013 | T18: 10013 | U18: null | V18: null | W18: 2000000 | X18: null | Y18: null | Z18: null | AA18: 5 | AB18: Не просрочена | AC18: https://crm.example.com/deal/57234 | AD18: 2025 | AE18: Проект | AF18: Соколова И.М.
A19: 57233 | B19: ВДС, дозаказ | C19: 107 | D19: 45733.681 | E19: Активные продажи | F19: Технический | G19: Строительство СНГ | H19: Частичная оплата | I19: 45747 | J19: ТД ВДС | K19: Сергеева Н.В. | L19: Строительство СНГ | M19: 45733.681 | N19: 45733.684 | O19: Подтвержден | P19: Новикова А.В. | Q19: 100000 | R19: 110000 | S19: 10014 | T19: 10014 | U19: null | V19: null | W19: null | X19: 110000 | Y19: null | Z19: null | AA19: 3 | AB19: Не просрочена | AC19: https://crm.example.com/deal/57233 | AD19: 2025 | AE19: Проект | AF19: Новикова А.В.
A20: 57232 | B20: Лабораторная мебель для Апатит | C20: 102 | D20: 45733.677 | E20: Активные продажи | F20: Лидогенерация | G20: Строительство | H20: Сбор информации | I20: 45867 | J20: null | K20: null | L20: Строительство | M20: 45733.681 | N20: 45733.681 | O20: OK | P20: Петрова Е.В. | Q20: 0 | R20: 0 | S20: null | T20: null | U20: null | V20: null | W20: null | X20: null | Y20: null | Z20: null | AA20: 3 | AB20: Не просрочена | AC20: https://crm.example.com/deal/57232 | AD20: 2025 | AE20: Проект | AF20: Петрова Е.В.
A21: 57231 | B21: Двери/откосы для КПП (успешно) | C21: 102 | D21: 45733.667 | E21: Успешно | F21: Успешно | G21: Строительство | H21: Успешно | I21: 45777 | J21: Алексвит | K21: Васильева К.А. | L21: Строительство | M21: 45733.667 | N21: 45734.271 | O21: OK | P21: Петрова Е.В. | Q21: 80000 | R21: 80000 | S21: 10010 | T21: 10010 | U21: null | V21: null | W21: null | X21: null | Y21: 80000 | Z21: 70000 | AA21: null | AB21: Нет | AC21: https://crm.example.com/deal/57231 | AD21: 2025 | AE21: Проект | AF21: Петрова Е.В.
A22: 57230 | B22: Заявка (Офис СБЕР) | C22: 101 | D22: 45733.646 | E22: Активные продажи | F22: Квалификация | G22: Дизайн-интерьеры | H22: Формирование КП | I22: 46163 | J22: Велесстрой | K22: Ормонбеков А. | L22: Дизайн-интерьеры | M22: 45733.417 | N22: 45733.188 | O22: OK | P22: Иванов П.С. | Q22: 0 | R22: 8000000 | S22: 10015 | T22: 10015 | U22: null | V22: null | W22: null | X22: null | Y22: null | Z22: null | AA22: null | AB22: Нет | AC22: https://crm.example.com/deal/57230 | AD22: 2025 | AE22: Проект | AF22: Ормонбеков А.
A23: 57229 | B23: КПП для ГКБ Ерамишанцева (дозаказ) | C23: 102 | D23: 45733.639 | E23: Активные продажи | F23: Проектирование | G23: Строительство | H23: КП сформировано | I23: 45819 | J23: Алексвит | K23: Васильева К.А. | L23: Строительство | M23: 45734.521 | N23: 45733.417 | O23: Есть КП | P23: Петрова Е.В. | Q23: 900000 | R23: 900000 | S23: 10010 | T23: 10010 | U23: null | V23: null | W23: null | X23: null | Y23: null | Z23: 900000 | AA23: 2 | AB23: Не просрочена | AC23: https://crm.example.com/deal/57229 | AD23: 2025 | AE23: Проект | AF23: Петрова Е.В.
A24: 57228 | B24: Офис СБЕР | C24: 110 | D24: 45733.604 | E24: Активные продажи | F24: Проектирование | G24: Строительство | H24: Передан в ДИ | I24: 46163 | J24: Велесстрой | K24: Ормонбеков А. | L24: Строительство | M24: 45733.417 | N24: 45733.646 | O24: OK | P24: Алексеева М.И. | Q24: 2000000 | R24: 8000000 | S24: 10015 | T24: 10015 | U24: null | V24: null | W24: null | X24: null | Y24: null | Z24: null | AA24: null | AB24: Нет | AC24: https://crm.example.com/deal/57228 | AD24: 2025 | AE24: Проект | AF24: Алексеева М.И.
A25: 57227 | B25: Стандартные отгрузки "Премьер Групп" | C25: 101 | D25: 45733.59 | E25: Активные продажи | F25: Технический | G25: Строительство | H25: Запуск в производство | I25: 45736 | J25: Премьер Групп | K25: Сергеева Н.В. | L25: Строительство | M25: 45734.521 | N25: 45733.59 | O25: В производстве | P25: Сергеева Н.В. | Q25: 80000 | R25: 80000 | S25: 10016 | T25: 10016 | U25: null | V25: null | W25: null | X25: 80000 | Y25: null | Z25: null | AA25: 15 | AB25: Не просрочена | AC25: https://crm.example.com/deal/57227 | AD25: 2025 | AE25: Стандарт | AF25: Сергеева Н.В.
A26: 57226 | B26: Мебель для вагона 4460 | C26: 114 | D26: 45733.583 | E26: Активные продажи | F26: Квалификация | G26: Транспорт | H26: Передан в КТО | I26: 45799 | J26: КСК МК | K26: Соколова И.М. | L26: Транспорт | M26: 45734.499 | N26: 45733.583 | O26: OK | P26: Попкова А.С. | Q26: 0 | R26: 0 | S26: 10017 | T26: 10017 | U26: null | V26: null | W26: null | X26: null | Y26: null | Z26: null | AA26: null | AB26: Нет | AC26: https://crm.example.com/deal/57226 | AD26: 2025 | AE26: Проект | AF26: Соколова И.М.
A27: 57225 | B27: Столешницы (ЛитТрансСервис) | C27: 114 | D27: 45733.58 | E27: Активные продажи | F27: Квалификация | G27: Отгрузка в кредит | H27: Ожидание оплаты | I27: 45747 | J27: ЛитТрансСервис | K27: Орлова Т.В. | L27: Отгрузка в кредит | M27: 45733.58 | N27: 45734.607 | O27: OK | P27: Попкова А.С. | Q27: 0 | R27: 50000 | S27: 10018 | T27: 10018 | U27: null | V27: null | W27: null | X27: null | Y27: null | Z27: null | AA27: null | AB27: Нет | AC27: https://crm.example.com/deal/57225 | AD27: 2025 | AE27: Проект | AF27: Орлова Т.В.
A28: 57224 | B28: Панели (Тверской экспресс) | C28: 114 | D28: 45733.576 | E28: Активные продажи | F28: Технический | G28: Транспорт | H28: Запуск в производство | I28: 45747 | J28: КСК МК | K28: Соколова И.М. | L28: Транспорт | M28: 45734.499 | N28: 45733.578 | O28: В производстве | P28: Попкова А.С. | Q28: 1200000 | R28: 1200000 | S28: 10017 | T28: 10017 | U28: null | V28: null | W28: null | X28: null | Y28: null | Z28: null | AA28: null | AB28: Нет | AC28: https://crm.example.com/deal/57224 | AD28: 2025 | AE28: Проект | AF28: Соколова И.М.
A29: 57223 | B29: КСК МК (столешницы из наличия) | C29: 114 | D29: 45733.573 | E29: Активные продажи | F29: Квалификация | G29: Отгрузка в кредит | H29: Ожидание оплаты | I29: 45722 | J29: КСК МК | K29: Соколова И.М. | L29: Отгрузка в кредит | M29: 45734.499 | N29: 45733.573 | O29: OK | P29: Попкова А.С. | Q29: 0 | R29: 80000 | S29: 10017 | T29: 10017 | U29: null | V29: null | W29: null | X29: null | Y29: null | Z29: null | AA29: null | AB29: Нет | AC29: https://crm.example.com/deal/57223 | AD29: 2025 | AE29: Проект | AF29: Соколова И.М.

Sheet b_uts_crm_deal
A1: VALUE_ID | C1: UF_CRM_1770214651 | D1: Прогноз продаж март 2026 | E1: Прогноз продаж апрель 2026 | F1: НомерЗК | G1: № ЗК | H1: № КП | I1: doc_OrderSales (в производстве для сделок).Сумма | J1: doc_OrderSales (в производстве для сделок).Ожидаемая дата производства | K1: doc_Sales (отгружено для сделок).Сумма | L1: doc_Sales (отгружено для сделок).Дата отгрузки | M1: doc_Comm_offer (для сделок).Сумма КП
A2: 57250 | B2: =VLOOKUP(A2,b_crm_deal!A:M,2,0) -> Жилой комплекс "Курский" | C2: Жилой комплекс "Курский" | D2: null | E2: null | F2: null | G2: null | H2: null | I2: null | J2: null | K2: null | L2: null | M2: null
A3: 57249 | B3: =VLOOKUP(A3,b_crm_deal!A:M,2,0) -> Сибур, Анапа (дозаказ) | C3: Сибур, Анапа (дозаказ) | D3: null | E3: null | F3: null | G3: ЗСУП-000768 | H3: ЗСУП-000768 | I3: null | J3: 1250000 | K3: 45785 | L3: null | M3: null | N3: null
A4: 57248 | B4: =VLOOKUP(A4,b_crm_deal!A:M,2,0) -> Артек (дозаказ) | C4: Артек (дозаказ) | D4: null | E4: null | F4: null | G4: ЗСУП-000715 | H4: ЗСУП-000707 | I4: null | J4: 900000 | K4: 45787 | L4: null | M4: null | N4: null
A5: 57248 | B5: =VLOOKUP(A5,b_crm_deal!A:M,2,0) -> Артек (дозаказ) | C5: Артек (дозаказ) | D5: null | E5: null | F5: null | G5: ЗСУП-000770 | H5: ЗСУП-000707 | I5: null | J5: 450000 | K5: 45789 | L5: null | M5: null | N5: null
A6: 57248 | B6: =VLOOKUP(A6,b_crm_deal!A:M,2,0) -> Артек (дозаказ) | C6: Артек (дозаказ) | D6: null | E6: null | F6: null | G6: ЗСУП-000716 | H6: ЗСУП-000707 | I6: null | J6: 140000 | K6: 45789 | L6: null | M6: null | N6: null
A7: 57248 | B7: =VLOOKUP(A7,b_crm_deal!A:M,2,0) -> Артек (дозаказ) | C7: Артек (дозаказ) | D7: null | E7: null | F7: null | G7: ЗСУП-000707 | H7: ЗСУП-000707 | I7: null | J7: 45000 | K7: 45787 | L7: null | M7: null | N7: null
A8: 57247 | B8: =VLOOKUP(A8,b_crm_deal!A:M,2,0) -> Сибур, Анапа (двери) | C8: Сибур, Анапа (двери) | D8: null | E8: null | F8: null | G8: ЗСУП-000851 | H8: ЗСУП-000851 | I8: null | J8: 1300000 | K8: 45792 | L8: null | M8: null | N8: null
A9: 57246 | B9: =VLOOKUP(A9,b_crm_deal!A:M,2,0) -> Стандартные отгрузки "РесторанСервис" | C9: Стандартные отгрузки "РесторанСервис" | D9: null | E9: null | F9: null | G9: ЗСУП-000936 | H9: null | I9: 90000 | J9: null | K9: null | L9: null | M9: null | N9: null
A10: 57245 | B10: =VLOOKUP(A10,b_crm_deal!A:M,2,0) -> HPL панели, г. Москва | C10: HPL панели, г. Москва | D10: null | E10: null | F10: null | G10: ЗСУП-000918 | H10: null | I10: null | J10: null | K10: null | L10: null | M10: null | N10: null
A11: 57244 | B11: =VLOOKUP(A11,b_crm_deal!A:M,2,0) -> Бизнес-центр "Вперед" | C11: Бизнес-центр "Вперед" | D11: null | E11: null | F11: null | G11: null | H11: null | I11: null | J11: null | K11: null | L11: null | M11: null | N11: null
A12: 57243 | B12: =VLOOKUP(A12,b_crm_deal!A:M,2,0) -> Входящий звонок (дилер) | C12: Входящий звонок (дилер) | D12: null | E12: null | F12: null | G12: null | H12: null | I12: null | J12: null | K12: null | L12: null | M12: null | N12: null
A13: 57242 | B13: =VLOOKUP(A13,b_crm_deal!A:M,2,0) -> Частный дом, Казахстан | C13: Частный дом, Казахстан | D13: null | E13: null | F13: null | G13: null | H13: null | I13: null | J13: null | K13: null | L13: null | M13: null | N13: null
A14: 57241 | B14: =VLOOKUP(A14,b_crm_deal!A:M,2,0) -> РБС Групп (двери) | C14: РБС Групп (двери) | D14: null | E14: null | F14: null | G14: null | H14: null | I14: null | J14: 500000 | K14: 45794 | L14: null | M14: null | N14: 500000
A15: 57240 | B15: =VLOOKUP(A15,b_crm_deal!A:M,2,0) -> Спа-центр "Коприно" | C15: Спа-центр "Коприно" | D15: null | E15: null | F15: null | G15: ЗСУП-000869 | H15: ЗСУП-000664 | I15: null | J15: null | K15: null | L15: null | M15: null | N15: null
A16: 57239 | B16: =VLOOKUP(A16,b_crm_deal!A:M,2,0) -> Стандартные отгрузки "Веста-Краснодар" | C16: Стандартные отгрузки "Веста-Краснодар" | D16: null | E16: null | F16: null | G16: null | H16: null | I16: null | J16: 50000 | K16: 45792 | L16: null | M16: null | N16: 40000
A17: 57238 | B17: =VLOOKUP(A17,b_crm_deal!A:M,2,0) -> Рентгенозащитные двери | C17: Рентгенозащитные двери | D17: null | E17: null | F17: null | G17: ЗСУП-000824 | H17: ЗСУП-000263 | I17: null | J17: 150000 | K17: 45792 | L17: null | M17: null | N17: null
A18: 57237 | B18: =VLOOKUP(A18,b_crm_deal!A:M,2,0) -> Откосы для КПП больниц | C18: Откосы для КПП больниц | D18: null | E18: null | F18: null | G18: ЗСУП-000812 | H18: ЗСУП-00 | I18: null | J18: 400000 | K18: 45788 | L18: null | M18: null | N18: 500000
A19: 57236 | B19: =VLOOKUP(A19,b_crm_deal!A:M,2,0) -> Центр детской онкологии, Беларусь | C19: Центр детской онкологии, Беларусь | D19: null | E19: null | F19: null | G19: ЗСУП-000564 | H19: ЗСУП-000410 | I19: null | J19: null | K19: null | L19: null | M19: null | N19: null
A20: 57235 | B20: =VLOOKUP(A20,b_crm_deal!A:M,2,0) -> Мебель для библиотеки Орска | C20: Мебель для библиотеки Орска | D20: null | E20: null | F20: null | G20: ЗСУП-000911 | H20: ЗСУП-000660 | I20: null | J20: null | K20: null | L20: null | M20: null | N20: null
A21: 57234 | B21: =VLOOKUP(A21,b_crm_deal!A:M,2,0) -> Аналитприбор, заказ 882 | C21: Аналитприбор, заказ 882 | D21: null | E21: null | F21: null | G21: null | H21: null | I21: 2000000 | J21: null | K21: null | L21: null | M21: null | N21: null
A22: 57233 | B22: =VLOOKUP(A22,b_crm_deal!A:M,2,0) -> ВДС, дозаказ | C22: ВДС, дозаказ | D22: null | E22: null | F22: null | G22: ЗСУП-000882 | H22: null | I22: null | J22: 110000 | K22: 45745 | L22: null | M22: null | N22: null
A23: 57232 | B23: =VLOOKUP(A23,b_crm_deal!A:M,2,0) -> Лабораторная мебель для Апатит | C23: Лабораторная мебель для Апатит | D23: null | E23: null | F23: null | G23: ЗСУП-000249 | H23: ЗСУП-000657 | I23: null | J23: null | K23: null | L23: null | M23: null | N23: null
A24: 57231 | B24: =VLOOKUP(A24,b_crm_deal!A:M,2,0) -> Двери/откосы для КПП (успешно) | C24: Двери/откосы для КПП (успешно) | D24: null | E24: null | F24: null | G24: null | H24: null | I24: null | J24: null | K24: null | L24: 80000 | M24: 45734.417 | N24: 70000
A25: 57230 | B25: =VLOOKUP(A25,b_crm_deal!A:M,2,0) -> Заявка (Офис СБЕР) | C25: Заявка (Офис СБЕР) | D25: null | E25: null | F25: null | G25: ЗСУП-000523 | H25: ЗСУП-000355 | I25: null | J25: null | K25: null | L25: null | M25: null | N25: null
A26: 57229 | B26: =VLOOKUP(A26,b_crm_deal!A:M,2,0) -> КПП для ГКБ Ерамишанцева (дозаказ) | C26: КПП для ГКБ Ерамишанцева (дозаказ) | D26: null | E26: null | F26: null | G26: null | H26: null | I26: null | J26: null | K26: null | L26: null | M26: null | N26: 900000
A27: 57228 | B27: =VLOOKUP(A27,b_crm_deal!A:M,2,0) -> Офис СБЕР | C27: Офис СБЕР | D27: null | E27: null | F27: null | I27: null | J27: null | K27: null | L27: null | M27: null | N27: null
A28: 57227 | B28: =VLOOKUP(A28,b_crm_deal!A:M,2,0) -> Стандартные отгрузки "Премьер Групп" | C28: Стандартные отгрузки "Премьер Групп" | D28: null | E28: null | F28: null | G28: null | H28: ЗСУП-000649 | I28: null | J28: 80000 | K28: 45756 | L28: null | M28: null | N28: null
A29: 57226 | B29: =VLOOKUP(A29,b_crm_deal!A:M,2,0) -> Мебель для вагона 4460 | C29: Мебель для вагона 4460 | D29: null | E29: null | F29: null | G29: null | H29: null | I29: null | J29: null | K29: null | L29: null | M29: null | N29: null
A30: 57225 | B30: =VLOOKUP(A30,b_crm_deal!A:M,2,0) -> Столешницы (ЛитТрансСервис) | C30: Столешницы (ЛитТрансСервис) | D30: null | E30: null | F30: null | I30: null | J30: null | K30: null | L30: null | M30: null | N30: null
A31: 57224 | B31: =VLOOKUP(A31,b_crm_deal!A:M,2,0) -> Панели (Тверской экспресс) | C31: Панели (Тверской экспресс) | D31: null | E31: null | F31: null | G31: ЗСУП-000609 | H31: null | I31: null | J31: null | K31: null | L31: null | M31: null | N31: null
A32: 57223 | B32: =VLOOKUP(A32,b_crm_deal!A:M,2,0) -> КСК МК (столешницы из наличия) | C32: КСК МК (столешницы из наличия) | D32: null | E32: null | F32: null | G32: null | H32: null | I32: null | J32: null | K32: null | L32: null | M32: null | N32: null

Sheet doc_OrderSales
A1: id_1c | B1: Name | C1: Number | D1: NumberExt | E1: Date | F1: Posted | G1: IsDelete | H1: vid_oper | I1: Priority | J1: organisation_id_1с | K1: status | L1: phersons_id_1с | M1: phersons_name | N1: author_id_1c | O1: author_name | P1: Partner_id | Q1: contractor_id_1с | R1: agreement_id_1с | S1: covenant_id_1c | T1: department_id_1с | U1: condition | V1: Nomenclature_id_1с | W1: UnitStore | X1: UnitReport | Y1: store_id_1с | Z1: store_name | AA1: Quantity | AB1: Amount | AC1: QuantityUnitReport | AD1: QuantityWeight | AE1: VidNomenclature | AF1: Date_shipment | AG1: SecurityOption | AH1: pos_cancelled | AI1: Price_plan | AJ1: Amount_plan | AK1: Price_Dop | AL1: percent_Action | AM1: Amount_Action | AN1: percent_Dop | AO1: vid_price | AP1: Price | AQ1: direction | AR1: Ref_1C | AS1: reason_cancelled | AT1: id_1c_doc_Comm_offer | AU1: spr_nomenclature.Name | AV1: spr_nomenclature.Группы ном | AW1: Копия Date | AX1: Сведение
A2: f38645b5-1d2d-11f1-99bb-00155dde6a00 | B2: Заказ клиента ЗСУП-000768 от 06.03.2026 14:49:05 | C2: ЗСУП-000768 | D2: ЗСУП-000768_2026 | E2: 46087.617 | F2: 0 | G2: 0 | H2: Реализация | I2: Средний | J2: 9e38a44e-b7d0-11e7-a547-f6d178db6df1 | K2: На согласовании | L2: 05f2ed7a-4034-11ef-8110-00155d000d00 | M2: Сорокина Инга Викторовна | N2: 7ada799d-7cef-11f0-a009-00155d81c805 | O2: Ипатова Анна Юрьевна | P2: 0b990115-2b95-11e9-ab3f-0cc47af964e9 | Q2: bed902e8-43aa-11ec-ab50-0cc47af964e9 | R2: 44587403-d89a-11ef-ab69-0cc47af964e9 | S2: 54206bf8-fefd-11ea-ab46-0cc47af964e9 | T2: 55c87efc-b566-11e7-a547-f6d178db6df1 | U2: Ожидается согласование | V2: 1030044b-4135-11f0-ab6b-0cc47af964e9 | W2: лист | X2: м2 | Y2: fa6fadf3-b578-11e7-a547-f6d178db6df1 | Z2: Склад упаковки готовой продукции (ЗСП) | AA2: 2 | AB2: 50 790,00 | AC2: 8.065 | AD2: 70.536 | AE2: Слопласт | AF2: null | AG2: К обеспечению | AH2: 0 | AI2: 10 920,05 | AJ2: 21 840,10 | AK2: 0 | AL2: 0 | AM2: 0 | AN2: 0 | AP2: 25 395,00 | AQ2: Стройка | AR2: e1cib/data/Документ.ЗаказКлиента?ref=99bb00155dde6a0011f11d2df38645b5 | AT2: 00000000-0000-0000-0000-000000000000 | AU2: Слопласт ТГ (/1320 х 3050 х 8,0/2/BITM/МТ//9736/9736//Н) | AV2: узкий/BITM/ТГ/МТ/(8.0) | AW2: 2025 | AX2: ЗСУП-003412_2 025
A3: 80941762-16e0-11f1-99b9-00155dde6a00 | B3: Заказ клиента ЗСУП-000715 от 03.03.2026 11:36:22 | C3: ЗСУП-000715 | D3: ЗСУП-000715_2026 | E3: 46084.483 | F3: 1 | G3: 0 | H3: Реализация | I3: Средний | J3: 9e38a44e-b7d0-11e7-a547-f6d178db6df1 | K3: К выполнению / В резерве | L3: 2a671c75-1d9b-11e2-a65b-0015171241a4 | M3: Макаренко Мария Борисовна | N3: d51dce26-0c67-11ef-810e-00155d000d00 | O3: Лебедева Елена Николаевна | P3: 0b990115-2b95-11e9-ab3f-0cc47af964e9 | Q3: bed902e8-43aa-11ec-ab50-0cc47af964e9 | R3: 00000000-0000-0000-0000-000000000000 | S3: 54206bf8-fefd-11ea-ab46-0cc47af964e9 | T3: 55c87efc-b566-11e7-a547-f6d178db6df1 | U3: Ожидается обеспечение | V3: 1030044b-4135-11f0-ab6b-0cc47af964e9 | W3: лист | X3: м2 | Y3: f027a6ed-b812-11e7-a547-f6d178db6df1 | Z3: Склад МО (Мытищи) | AA3: 6 | AB3: 188 988,00 | AC3: 24.194 | AD3: 211.608 | AE3: Слопласт | AF3: null | AG3: К обеспечению | AH3: 0 | AI3: 19 875,29 | AJ3: 119 251,74 | AK3: 0 | AL3: 0 | AM3: 0 | AN3: 0 | AP3: 31 498,00 | AQ3: Стройка | AR3: e1cib/data/Документ.ЗаказКлиента?ref=99b900155dde6a0011f116e080941762 | AT3: 00000000-0000-0000-0000-000000000000 | AU3: Слопласт Ф (/1320 х 3050 х 10,0/2/BITM/МТ/УФ/2754/1113Т//Н) | AV3: узкий/BITM/Ф/МТ/(9.0-11.0) | AW3: 2025 | AX3: ЗСУП-003776_2 025
A4: 653048a2-1955-11f1-99bb-00155dde6a00 | B4: Заказ клиента ЗСУП-000770 от 06.03.2026 15:00:47 | C4: ЗСУП-000770 | D4: ЗСУП-000770_2026 | E4: 46087.625 | F4: 1 | G4: 0 | H4: Реализация | I4: Средний | J4: 9e38a44e-b7d0-11e7-a547-f6d178db6df1 | K4: К выполнению / В резерве | L4: 05f2ed7a-4034-11ef-8110-00155d000d00 | M4: Сорокина Инга Викторовна | N4: 7ada799d-7cef-11f0-a009-00155d81c805 | O4: Ипатова Анна Юрьевна | P4: 0b990115-2b95-11e9-ab3f-0cc47af964e9 | Q4: bed902e8-43aa-11ec-ab50-0cc47af964e9 | R4: 3cd61b03-e097-11f0-99b9-00155dde6a00 | S4: 54206bf8-fefd-11ea-ab46-0cc47af964e9 | T4: 55c87efc-b566-11e7-a547-f6d178db6df1 | U4: Ожидается обеспечение | V4: 1030044b-4135-11f0-ab6b-0cc47af964e9 | W4: лист | X4: м2 | Y4: fa6fadf3-b578-11e7-a547-f6d178db6df1 | Z4: Склад упаковки готовой продукции (ЗСП) | AA4: 6 | AB4: 152 370,00 | AC4: 24.194 | AD4: 211.608 | AE4: Слопласт | AF4: null | AG4: К обеспечению | AH4: 0 | AI4: 16 866,75 | AJ4: 101 200,50 | AK4: 0 | AL4: 0 | AM4: 0 | AN4: 0 | AP4: 25 395,00 | AQ4: Стройка | AR4: e1cib/data/Документ.ЗаказКлиента?ref=99bb00155dde6a0011f11955653048a2 | AT4: 00000000-0000-0000-0000-000000000000 | AU4: Слопласт ТГ (/1320 х 3050 х 8,0/2/BITM/МТ//9736/9736//Н) | AV4: узкий/BITM/ТГ/МТ/(8.0) | AW4: 2026 | AX4: ЗСУП-000370_2 026
A5: bbe8240f-16e1-11f1-99b9-00155dde6a00 | B5: Заказ клиента ЗСУП-000716 от 03.03.2026 12:17:01 | C5: ЗСУП-000716 | D5: ЗСУП-000716_2026 | E5: 46084.512 | F5: 1 | G5: 0 | H5: Реализация | I5: Средний | J5: 9e38a44e-b7d0-11e7-a547-f6d178db6df1 | K5: К выполнению / В резерве | L5: 8870b4a7-f73b-11e6-80de-00155d000d00 | M5: Козлова Мария Николаевна | N5: c2b02347-0c63-11ef-ab64-0cc47af964e9 | O5: Касимова Карина Ринатовна | P5: c64f81c5-f924-11ed-ab5f-0cc47af964e9 | Q5: c64f81fe-f924-11ed-ab5f-0cc47af964e9 | R5: 5538e8d6-e24e-11f0-99b9-00155dde6a00 | S5: 54206bf8-fefd-11ea-ab46-0cc47af964e9 | T5: 55c87efc-b566-11e7-a547-f6d178db6df1 | U5: Ожидается обеспечение | V5: 05f12735-b32c-11eb-ab4d-0cc47af964e9 | W5: лист | X5: м2 | Y5: fa6fadf3-b578-11e7-a547-f6d178db6df1 | Z5: Склад упаковки готовой продукции (ЗСП) | AA5: 1 | AB5: 12 700,80 | AC5: 4.032 | AD5: 23.512 | AE5: Слопласт | AF5: null | AG5: К обеспечению | AH5: 0 | AI5: 8 059,24 | AJ5: 8 059,24 | AK5: 0 | AL5: 0 | AM5: 0 | AN5: 0 | AP5: 12 700,80 | AQ5: Стройка | AR5: e1cib/data/Документ.ЗаказКлиента?ref=99b900155dde6a0011f116e1bbe8240f | AT5: 00000000-0000-0000-0000-000000000000 | AU5: Слопласт ТГ (12/1320 х 3050 х 4,0/2/BITM/МТ//847/847//Н) | AV5: узкий/BITM/ТГ/МТ/(4.0) | AW5: 2026 | AX5: ЗСУП-000643_2 026
A6: b418c3b9-1636-11f1-99b9-00155dde6a00 | B6: Заказ клиента ЗСУП-000707 от 02.03.2026 15:52:50 | C6: ЗСУП-000707 | D6: ЗСУП-000707_2026 | E6: 46083.661 | F6: 1 | G6: 0 | H6: Реализация | I6: Средний | J6: 9e38a44e-b7d0-11e7-a547-f6d178db6df1 | K6: К выполнению / В резерве | L6: 2a671c75-1d9b-11e2-a65b-0015171241a4 | M6: Макаренко Мария Борисовна | N6: c2b02347-0c63-11ef-ab64-0cc47af964e9 | O6: Касимова Карина Ринатовна | P6: c64f81c5-f924-11ed-ab5f-0cc47af964e9 | Q6: c64f81fe-f924-11ed-ab5f-0cc47af964e9 | R6: 320acb99-1637-11f1-99b9-00155dde6a00 | S6: 258beace-a26f-11eb-ab4c-0cc47af964e9 | T6: 55c87efc-b566-11e7-a547-f6d178db6df1 | U6: Ожидается обеспечение | V6: 1033fcfb-f348-11ef-ab6a-0cc47af964e9 | W6: лист | X6: м2 | Y6: fa6fadf3-b578-11e7-a547-f6d178db6df1 | Z6: Склад упаковки готовой продукции (ЗСП) | AA6: 60 | AB6: 209 349,60 | AC6: 241.935 | AD6: 282.12 | AE6: Слопласт | AF6: null | AG6: К обеспечению | AH6: 0 | AI6: 1 621,21 | AJ6: 97 272,60 | AK6: 0 | AL6: 0 | AM6: 0 | AN6: 0 | AP6: 3 489,16 | AQ6: Стройка | AR6: e1cib/data/Документ.ЗаказКлиента?ref=99b900155dde6a0011f11636b418c3b9 | AT6: 00000000-0000-0000-0000-000000000000 | AU6: Слопласт ТГ (/1320 х 3050 х 0,8/1/BITM/СД//9733//Ш) | AV6: узкий/BITM/ТГ/СД/(0.5-1.0) | AW6: 2026 | AX6: ЗСУП-000270_2 026
A7: c236b5ca-1e1d-11f1-99bb-00155dde6a00 | B7: Заказ клиента ЗСУП-000851 от 12.03.2026 17:08:18 | C7: ЗСУП-000851 | D7: ЗСУП-000851_2026 | E7: 46093.714 | F7: 1 | G7: 0 | H7: Реализация | I7: Средний | J7: 9e38a44e-b7d0-11e7-a547-f6d178db6df1 | K7: К выполнению / В резерве | L7: 59599dd2-c972-11ed-8109-00155d000d00 | M7: Стальберг Елена Александровна | N7: 59599dd2-c972-11ed-8109-00155d000d00 | O7: Стальберг Елена Александровна | P7: 1b556bc5-f368-11e8-9fe3-d000e1470f5d | Q7: 1b556bc6-f368-11e8-9fe3-d000e1470f5d | R7: 3081c846-2107-11f1-99bb-00155dde6a00 | S7: c42f193e-01ce-11e9-ab3f-0cc47af964e9 | T7: 55c87efc-b566-11e7-a547-f6d178db6df1 | U7: Ожидается обеспечение | V7: 03ed5797-640e-11e8-ab3e-0cc47af964e9 | W7: лист | X7: м2 | Y7: fa6fadf3-b578-11e7-a547-f6d178db6df1 | Z7: Склад упаковки готовой продукции (ЗСП) | AA7: 4 | AB7: 204 224,00 | AC7: 19.139 | AD7: 391.508 | AE7: Слопласт | AF7: null | AG7: К обеспечению | AH7: 0 | AI7: 33 164,09 | AJ7: 132 656,36 | AK7: 0 | AL7: 0 | AM7: 0 | AN7: 0 | AO7: С2 | AP7: 51 056,00 | AQ7: Транспорт | AR7: e1cib/data/Документ.ЗаказКлиента?ref=99bb00155dde6a0011f11e1dc236b5ca | AT7: 00000000-0000-0000-0000-000000000000 | AU7: Слопласт ТГ (/1570 х 3050 х 14,0/2/BITM/Т//2762/2762//Н) | AV7: широкий/BITM/ТГ/Т/(13.0-25.0) | AW7: 2025 | AX7: ЗСУП-001865_2 025
A8: c6d95ff4-2269-11f1-99bb-00155dde6a00 | B8: Заказ клиента ЗСУП-000936 от 18.03.2026 17:46:46 | C8: ЗСУП-000936 | D8: ЗСУП-000936_2026 | E8: 46099.74 | F8: 0 | G8: 0 | H8: Реализация | I8: Средний | J8: 9e38a44e-b7d0-11e7-a547-f6d178db6df1 | K8: На согласовании | L8: 59599dd2-c972-11ed-8109-00155d000d00 | M8: Стальберг Елена Александровна | N8: 7fc9daa0-066f-11f1-a014-00155d81c802 | O8: Кулагина Анна Александровна | P8: 1b556bc5-f368-11e8-9fe3-d000e1470f5d | Q8: 1b556bc6-f368-11e8-9fe3-d000e1470f5d | R8: 3081c846-2107-11f1-99bb-00155dde6a00 | S8: c42f193e-01ce-11e9-ab3f-0cc47af964e9 | T8: 55c87efc-b566-11e7-a547-f6d178db6df1 | V8: 03ed5797-640e-11e8-ab3e-0cc47af964e9 | W8: лист | X8: м2 | Y8: fa6fadf3-b578-11e7-a547-f6d178db6df1 | Z8: Склад упаковки готовой продукции (ЗСП) | AA8: 8 | AB8: 417 600,00 | AC8: 38.278 | AD8: 783.016 | AE8: Слопласт | AF8: null | AG8: К обеспечению | AH8: 0 | AI8: 31 988,29 | AJ8: 255 906,32 | AK8: 0 | AL8: 0 | AM8: 0 | AN8: 0 | AO8: С2 | AP8: 52 200,00 | AQ8: Транспорт | AR8: e1cib/data/Документ.ЗаказКлиента?ref=99bb00155dde6a0011f12269c6d95ff4 | AT8: 00000000-0000-0000-0000-000000000000 | AU8: Слопласт ТГ (/1570 х 3050 х 14,0/2/BITM/Т//2762/2762//Н) | AV8: широкий/BITM/ТГ/Т/(13.0-25.0) | AW8: 2025 | AX8: ЗСУП-003811_2 025
A9: d0bbdb8d-1fe5-11f1-99bb-00155dde6a00 | B9: Заказ клиента ЗСУП-000918 от 15.03.2026 17:49:55 | C9: ЗСУП-000918 | D9: ЗСУП-000918_2026 | E9: 46096.742 | F9: 0 | G9: 0 | H9: Реализация | I9: Средний | J9: 9e38a44e-b7d0-11e7-a547-f6d178db6df1 | K9: На согласовании | L9: 59599dd2-c972-11ed-8109-00155d000d00 | M9: Стальберг Елена Александровна | N9: 7fc9daa0-066f-11f1-a014-00155d81c802 | O9: Кулагина Анна Александровна | P9: 7a9e79e3-22c5-11ed-ab55-0cc47af964e9 | Q9: dbbed476-bb09-11ec-ab50-0cc47af964e9 | R9: d532e74f-22e8-11ed-ab55-0cc47af964e9 | S9: d4764638-87cb-11f0-99b7-00155dde6a00 | T9: 609d494f-b566-11e7-a547-f6d178db6df1 | V9: 1862f4f7-8a28-11f0-99b7-00155dde6a00 | W9: лист | X9: м2 | Y9: fa6fadf3-b578-11e7-a547-f6d178db6df1 | Z9: Склад упаковки готовой продукции (ЗСП) | AA9: 3 | AB9: 23 523,00 | AC9: 14.354 | AD9: 62.922 | AE9: Слопласт | AF9: null | AG9: К обеспечению | AH9: 0 | AI9: 5 840,75 | AJ9: 17 522,25 | AK9: 0 | AL9: 0 | AM9: 0 | AN9: 0 | AP9: 7 841,00 | AQ9: Транспорт | AR9: e1cib/data/Документ.ЗаказКлиента?ref=99bb00155dde6a0011f11fe5d0bbdb8d | AT9: 00000000-0000-0000-0000-000000000000 | AU9: Слопласт ТГ (/1570 х 3050 х 3,0/1/BITM/Т//688//Ш) | AV9: широкий/BITM/ТГ/Т/(2.5-3.0) | AW9: 2025 | AX9: ЗСУП-004450_2 025
A10: 3a7e6a32-1f4f-11f1-99bb-00155dde6a00 | B10: Заказ клиента ЗСУП-000869 от 15.03.2026 11:47:47 | C10: ЗСУП-000869 | D10: ЗСУП-000869_2026 | E10: 46096.491 | F10: 0 | G10: 0 | H10: Реализация | I10: Средний | J10: 9e38a44e-b7d0-11e7-a547-f6d178db6df1 | K10: На согласовании | L10: 05f2ed7a-4034-11ef-8110-00155d000d00 | M10: Сорокина Инга Викторовна | N10: 7ada799d-7cef-11f0-a009-00155d81c805 | O10: Ипатова Анна Юрьевна | P10: 3fa69b08-b7a5-11e2-ae63-0015171241a4 | Q10: 35ad1025-f36b-11e8-9fe3-d000e1470f5d | R10: f8e09145-5001-11ef-ab64-0cc47af964e9 | S10: 52094fa9-769a-11eb-ab4c-0cc47af964e9 | T10: 55c87efc-b566-11e7-a547-f6d178db6df1 | V10: 037f533d-013b-11ef-ab64-0cc47af964e9 | W10: лист | X10: м2 | Y10: fa6fadf3-b578-11e7-a547-f6d178db6df1 | Z10: Склад упаковки готовой продукции (ЗСП) | AA10: 600 | AB10: 759 600,00 | AC10: 2419.355 | AD10: 1763.4 | AE10: Слопласт | AF10: null | AG10: К обеспечению | AH10: 0 | AI10: 1 025,10 | AJ10: 615 060,00 | AK10: 0 | AL10: 0 | AM10: 0 | AN10: 0 | AP10: 1 266,00 | AQ10: Мебель | AR10: e1cib/data/Документ.ЗаказКлиента?ref=99bb00155dde6a0011f11f4f3a7e6a32 | AT10: 00000000-0000-0000-0000-000000000000 | AU10: Слопласт П (/1320 х 3050 х 0,5/BIPA/Г//711//Ш) | AV10: узкий/BIPA/П/Г/(0.5-1.0) | AW10: 2025 | AX10: ЗСУП-001729_2 025
A11: 14fdc30b-1d31-11f1-99bb-00155dde6a00 | B11: Заказ клиента ЗСУП-000824 от 11.03.2026 14:30:03 | C11: ЗСУП-000824 | D11: ЗСУП-000824_2026 | E11: 46092.604 | F11: 1 | G11: 0 | H11: Реализация | I11: Средний | J11: 9e38a44e-b7d0-11e7-a547-f6d178db6df1 | K11: К выполнению / В резерве | L11: 01d4de8c-6aaf-11ef-8110-00155d000d00 | M11: Рожкова Софья Алексеевна | N11: deb389e3-b3c8-11ef-8111-00155d000d00 | O11: Троицкая Мария Николаевна | P11: 31844b91-355e-11de-8227-0015171241a4 | Q11: 107108ee-f367-11e8-9fe3-d000e1470f5d | R11: 09095034-f078-11f0-99b9-00155dde6a00 | S11: 2f3364f4-226a-11ea-ab44-0cc47af964e9 | T11: 609d494f-b566-11e7-a547-f6d178db6df1 | U11: Ожидается обеспечение | V11: 194970a4-6577-11ed-ab59-0cc47af964e9 | W11: лист | X11: м2 | Y11: fa6fadf3-b578-11e7-a547-f6d178db6df1 | Z11: Склад упаковки готовой продукции (ЗСП) | AA11: 12 | AB11: 19 440,00 | AC11: 48.387 | AD11: 35.268 | AE11: Слопласт | AF11: null | AG11: К обеспечению | AH11: 0 | AI11: 958.46 | AJ11: 11 501,52 | AK11: 0 | AL11: 0 | AM11: 0 | AN11: 0 | AO11: С4 | AP11: 1 620,00 | AQ11: Мебель | AR11: e1cib/data/Документ.ЗаказКлиента?ref=99bb00155dde6a0011f11d3114fdc30b | AT11: 00000000-0000-0000-0000-000000000000 | AU11: Слопласт П (/1320 х 3050 х 0,5/BIPA/ТС//707//Ш) | AV11: узкий/BIPA/П/ТС/(0.5-1.0) | AW11: 2026 | AX11: ЗСУП-000004_2 026
A12: d30b1e43-164d-11f1-99b9-00155dde6a00 | B12: Заказ клиента ЗСУП-000812 от 27.02.2026 0:00:00 | C12: ЗСУП-000812 | D12: ЗСУП-000812_2026 | E12: 46080 | F12: 0 | G12: 0 | H12: Реализация | I12: Средний | J12: 9e38a44e-b7d0-11e7-a547-f6d178db6df1 | K12: На согласовании | L12: 05f2ed7a-4034-11ef-8110-00155d000d00 | M12: Сорокина Инга Викторовна | N12: 7ada799d-7cef-11f0-a009-00155d81c805 | O12: Ипатова Анна Юрьевна | P12: 043fe15a-a8fe-11e3-a2e4-0015171241a4 | Q12: 04e19795-f36b-11e8-9fe3-d000e1470f5d | R12: f8e09145-5001-11ef-ab64-0cc47af964e9 | S12: 0d1dd908-1fa2-11ed-ab55-0cc47af964e9 | T12: 55c87efc-b566-11e7-a547-f6d178db6df1 | V12: 037f533d-013b-11ef-ab64-0cc47af964e9 | W12: лист | X12: м2 | Y12: fa6fadf3-b578-11e7-a547-f6d178db6df1 | Z12: Склад упаковки готовой продукции (ЗСП) | AA12: 600 | AB12: 759 600,00 | AC12: 2419.355 | AD12: 1763.4 | AE12: Слопласт | AF12: null | AG12: К обеспечению | AH12: 0 | AI12: 1 025,10 | AJ12: 615 060,00 | AK12: 0 | AL12: 0 | AM12: 0 | AN12: 0 | AP12: 1 266,00 | AQ12: Мебель | AR12: e1cib/data/Документ.ЗаказКлиента?ref=99b900155dde6a0011f1164dd30b1e43 | AT12: 00000000-0000-0000-0000-000000000000 | AU12: Слопласт П (/1320 х 3050 х 0,5/BIPA/Г//711//Ш) | AV12: узкий/BIPA/П/Г/(0.5-1.0) | AW12: 2025 | AX12: ЗСУП-004450_2 025
A13: e2e7dc1d-0bbd-11f1-99b9-00155dde6a00 | B13: Заказ клиента ЗСУП-000564 от 16.02.2026 17:02:45 | C13: ЗСУП-000564 | D13: ЗСУП-000564_2026 | E13: 46069.71 | F13: 1 | G13: 0 | H13: Реализация | I13: Средний | J13: 9e38a44e-b7d0-11e7-a547-f6d178db6df1 | K13: К выполнению / В резерве | L13: 59599dd2-c972-11ed-8109-00155d000d00 | M13: Стальберг Елена Александровна | N13: 59599dd2-c972-11ed-8109-00155d000d00 | O13: Стальберг Елена Александровна | P13: 7c3ca0c6-c6ed-11e3-8894-0015171241a5 | Q13: 6c972905-f36a-11e8-9fe3-d000e1470f5d | R13: bf6910b9-e175-11ef-ab6a-0cc47af964e9 | S13: b716f4dd-1588-11e9-ab3f-0cc47af964e9 | T13: 609d494f-b566-11e7-a547-f6d178db6df1 | U13: Ожидается обеспечение | V13: 020a0fd1-ae0e-11e9-ab3f-0cc47af964e9 | W13: лист | X13: м2 | Y13: fa6fadf3-b578-11e7-a547-f6d178db6df1 | Z13: Склад упаковки готовой продукции (ЗСП) | AA13: 1 | AB13: 22 149,00 | AC13: 4.032 | AD13: 58.78 | AE13: Слопласт | AF13: null | AG13: К обеспечению | AH13: 0 | AI13: 18 182,41 | AJ13: 18 182,41 | AK13: 0 | AL13: 0 | AM13: 0 | AN13: 0 | AP13: 22 149,00 | AQ13: ГК | AR13: e1cib/data/Документ.ЗаказКлиента?ref=99b900155dde6a0011f10bbde2e7dc1d | AT13: 00000000-0000-0000-0000-000000000000 | AU13: Слопласт Д (/1320 х 3050 х 12,0/2/BIFM/Т//2760/2760//Н) | AV13: узкий/BIFM/Д/Т/(12.0) | AW13: 2025 | AX13: ЗСУП-004450_2 025
A14: ed25a087-212c-11f1-99bb-00155dde6a00 | B14: Заказ клиента ЗСУП-000911 от 16.03.2026 14:29:36 | C14: ЗСУП-000911 | D14: ЗСУП-000911_2026 | E14: 46097.603 | F14: 1 | G14: 0 | H14: Реализация | I14: Средний | J14: 9e38a44e-b7d0-11e7-a547-f6d178db6df1 | K14: К выполнению / В резерве | L14: 05f2ed7a-4034-11ef-8110-00155d000d00 | M14: Сорокина Инга Викторовна | N14: 7ada799d-7cef-11f0-a009-00155d81c805 | O14: Ипатова Анна Юрьевна | P14: 043fe15a-a8fe-11e3-a2e4-0015171241a4 | Q14: 04e19795-f36b-11e8-9fe3-d000e1470f5d | R14: f8e09145-5001-11ef-ab64-0cc47af964e9 | S14: 0d1dd908-1fa2-11ed-ab55-0cc47af964e9 | T14: 55c87efc-b566-11e7-a547-f6d178db6df1 | U14: Ожидается обеспечение | V14: 0893a63f-048c-11ef-ab64-0cc47af964e9 | W14: лист | X14: м2 | Y14: fa6fadf3-b578-11e7-a547-f6d178db6df1 | Z14: Склад упаковки готовой продукции (ЗСП) | AA14: 36 | AB14: 54 000,00 | AC14: 145.161 | AD14: 105.804 | AE14: Слопласт | AF14: null | AG14: К обеспечению | AH14: 0 | AI14: 1 025,10 | AJ14: 36 903,60 | AK14: 0 | AL14: 0 | AM14: 0 | AN14: 0 | AP14: 1 500,00 | AQ14: Мебель | AR14: e1cib/data/Документ.ЗаказКлиента?ref=99bb00155dde6a0011f1212ced25a087 | AT14: 00000000-0000-0000-0000-000000000000 | AU14: Слопласт П (/1320 х 3050 х 0,5/BIPA/Г//711//Ш) | AV14: узкий/BIPA/П/Г/(0.5-1.0) | AW14: 2025 | AX14: ЗСУП-004450_2 025
A15: cc3a40a9-1ee5-11f1-99bb-00155dde6a00 | B15: Заказ клиента ЗСУП-000882 от 13.03.2026 17:06:15 | C15: ЗСУП-000882 | D15: ЗСУП-000882_2026 | E15: 46094.713 | F15: 0 | G15: 0 | H15: Реализация | I15: Средний | J15: 9e38a44e-b7d0-11e7-a547-f6d178db6df1 | K15: На согласовании | L15: 59599dd2-c972-11ed-8109-00155d000d00 | M15: Стальберг Елена Александровна | N15: 7fc9daa0-066f-11f1-a014-00155d81c802 | O15: Кулагина Анна Александровна | P15: 1b556bc5-f368-11e8-9fe3-d000e1470f5d | Q15: 1b556bc6-f368-11e8-9fe3-d000e1470f5d | R15: 3081c846-2107-11f1-99bb-00155dde6a00 | S15: c42f193e-01ce-11e9-ab3f-0cc47af964e9 | T15: 55c87efc-b566-11e7-a547-f6d178db6df1 | V15: 03ed5797-640e-11e8-ab3e-0cc47af964e9 | W15: лист | X15: м2 | Y15: fa6fadf3-b578-11e7-a547-f6d178db6df1 | Z15: Склад упаковки готовой продукции (ЗСП) | AA15: 8 | AB15: 417 600,00 | AC15: 38.278 | AD15: 783.016 | AE15: Слопласт | AF15: null | AG15: К обеспечению | AH15: 0 | AI15: 31 988,29 | AJ15: 255 906,32 | AK15: 0 | AL15: 0 | AM15: 0 | AN15: 0 | AO15: С2 | AP15: 52 200,00 | AQ15: Транспорт | AR15: e1cib/data/Документ.ЗаказКлиента?ref=99bb00155dde6a0011f11ee5cc3a40a9 | AT15: 00000000-0000-0000-0000-000000000000 | AU15: Слопласт ТГ (/1570 х 3050 х 14,0/2/BITM/Т//2762/2762//Н) | AV15: широкий/BITM/ТГ/Т/(13.0-25.0) | AW15: 2026 | AX15: ЗСУП-000321_2 026
A16: 45b6d95f-fc4c-11f0-99b9-00155dde6a00 | B16: Заказ клиента ЗСУП-000249 от 28.01.2026 16:06:42 | C16: ЗСУП-000249 | D16: ЗСУП-000249_2026 | E16: 46050.671 | F16: 1 | G16: 0 | H16: Реализация | I16: Средний | J16: 9e38a44e-b7d0-11e7-a547-f6d178db6df1 | K16: Закрыт | L16: 05f2ed7a-4034-11ef-8110-00155d000d00 | M16: Сорокина Инга Викторовна | N16: bafef812-be80-11ee-ab64-0cc47af964e9 | O16: Сидоренко Юлия Сергеевна | P16: 043fe15a-a8fe-11e3-a2e4-0015171241a4 | Q16: 04e19795-f36b-11e8-9fe3-d000e1470f5d | R16: f8e09145-5001-11ef-ab64-0cc47af964e9 | S16: 0d1dd908-1fa2-11ed-ab55-0cc47af964e9 | T16: 609d494f-b566-11e7-a547-f6d178db6df1 | U16: Закрыт | V16: 037f533d-013b-11ef-ab64-0cc47af964e9 | W16: лист | X16: м2 | Y16: fa6fadf3-b578-11e7-a547-f6d178db6df1 | Z16: Склад упаковки готовой продукции (ЗСП) | AA16: 12 | AB16: 15 192,00 | AC16: 48.387 | AD16: 35.268 | AE16: Слопласт | AF16: 46066 | AG16: Отгрузить | AH16: 0 | AI16: 919.22 | AJ16: 11 030,64 | AK16: 0 | AL16: 0 | AM16: 0 | AN16: 0 | AP16: 1 266,00 | AQ16: Мебель | AR16: e1cib/data/Документ.ЗаказКлиента?ref=99b900155dde6a0011f0fc4c45b6d95f | AT16: 00000000-0000-0000-0000-000000000000 | AU16: Слопласт П (/1320 х 3050 х 0,5/BIPA/Г//711//Ш) | AV16: узкий/BIPA/П/Г/(0.5-1.0) | AW16: 2025 | AX16: ЗСУП-001594_2 025
A17: 886a2158-0bd4-11f1-99b9-00155dde6a00 | B17: Заказ клиента ЗСУП-000524 от 12.03.2026 0:00:00 | C17: ЗСУП-000524 | D17: ЗСУП-000524_2026 | E17: 46093 | F17: 1 | G17: 0 | H17: Реализация | I17: Средний | J17: 9e38a44e-b7d0-11e7-a547-f6d178db6df1 | K17: На согласовании | L17: 8870b4a7-f73b-11e6-80de-00155d000d00 | M17: Козлова Мария Николаевна | N17: c2b02347-0c63-11ef-ab64-0cc47af964e9 | O17: Касимова Карина Ринатовна | P17: 0600068e-2127-45ca-91ca-271aa52dfc58 | Q17: 48591ce1-a540-448b-9f0c-5fef704a3eba | R17: 6b74db2f-0bd4-11f1-99b9-00155dde6a00 | S17: 54206bf8-fefd-11ea-ab46-0cc47af964e9 | T17: 55c87efc-b566-11e7-a547-f6d178db6df1 | U17: Ожидается согласование | V17: 030917fe-1900-11eb-ab48-0cc47af964e9 | W17: лист | X17: м2 | Y17: fa6fadf3-b578-11e7-a547-f6d178db6df1 | Z17: Склад упаковки готовой продукции (ЗСП) | AA17: 32 | AB17: 828 928,00 | AC17: 129.032 | AD17: 1504.768 | AE17: Слопласт | AF17: null | AG17: К обеспечению | AH17: 0 | AI17: 0 | AJ17: 0 | AK17: 0 | AL17: 0 | AM17: 0 | AN17: 0 | AP17: 25 904,00 | AQ17: Стройка | AR17: e1cib/data/Документ.ЗаказКлиента?ref=99b900155dde6a0011f10bd4886a2158 | AT17: c66f8b60-0b1c-11f1-99b9-00155dde6a00 | AU17: Слопласт ТГ (/1320 х 3050 х 8,0/2/BITM/Т//2756/2756//Н) | AV17: узкий/BITM/ТГ/Т/(8.0) | AW17: 2026 | AX17: ЗСУП-000700_2 026
A18: 882b5916-116f-11f1-99b9-00155dde6a00 | B18: Заказ клиента ЗСУП-000609 от 24.02.2026 13:56:36 | C18: ЗСУП-000609 | D18: ЗСУП-000609_2026 | E18: 46077.581 | F18: 1 | G18: 0 | H18: Реализация | I18: Высокий | J18: 9e38a44e-b7d0-11e7-a547-f6d178db6df1 | K18: Закрыт | L18: 5b3155c0-23a7-11e5-80ca-00155d000d00 | M18: Новинская Светлана Анатольевна | N18: 7ada799d-7cef-11f0-a009-00155d81c805 | O18: Ипатова Анна Юрьевна | P18: bed902e8-43aa-11ec-ab50-0cc47af964e9 | Q18: 275aab44-f368-11e8-9fe3-d000e1470f5d | R18: 695f4407-2bab-11ee-ab62-0cc47af964e9 | S18: 54206bf8-fefd-11ea-ab46-0cc47af964e9 | T18: 55c87efc-b566-11e7-a547-f6d178db6df1 | U18: Закрыт | V18: 13ca80d0-c09b-11e7-80e3-00155d000d00 | W18: лист | X18: м2 | Y18: f027a6ed-b812-11e7-a547-f6d178db6df1 | Z18: Склад МО (Мытищи) | AA18: 8 | AB18: 49 536,00 | AC18: 38.278 | AD18: 111.856 | AE18: Слопласт | AF18: 46108 | AG18: Отгрузить | AH18: 0 | AI18: 3 950,61 | AJ18: 31 604,88 | AK18: 0 | AL18: 0 | AM18: 0 | AN18: 0 | AO18: С4 | AP18: 6 192,00 | AQ18: Транспорт | AR18: e1cib/data/Документ.ЗаказКлиента?ref=99b900155dde6a0011f1116f882b5916 | AT18: 00000000-0000-0000-0000-000000000000 | AU18: Слопласт ТГ (/1570 х 3050 х 2,0/1/BITM/М//2760//Ш) | AV18: широкий/BITM/ТГ/М/(2.0) | AW18: 2025 | AX18: ЗСУП-001743_2 025

Sheet doc_Sales
A1: base | B1: dt | C1: id_1c | D1: Name | E1: Number | F1: Date | G1: Posted | H1: IsDelete | I1: vid_oper | J1: Priority | K1: organisation_id_1с | L1: status | M1: phersons_id_1с | N1: Partner_id | O1: contractor_id_1с | P1: agreement_id_1с | Q1: covenant_id_1c | R1: department_id_1c | S1: Nomenclature_id_1c | T1: UnitStore | U1: UnitReport | V1: store_id_1c | W1: store_name | X1: Quantity | Y1: Amount | Z1: QuantityUnitReport | AA1: QuantityWeight | AB1: VidNomenclature | AC1: vid_price | AD1: AmountNDS | AE1: Price | AF1: direction | AG1: Zakaz_id_1c | AH1: Ref_1c | AI1: Сведено | AJ1: spr_nomenclature.code1С
A2: ERP | B2: 46000.557 | C2: e5b05548-d4e2-11f0-99b9-00155dde6a00 | D2: Реализация товаров и услуг ЗСУП-004953 от 09.12.2025 12:39:10 | E2: ЗСУП-004953 | F2: 46000.527 | G2: 1 | H2: 0 | I2: Реализация | J2: null | K2: 9e38a44e-b7d0-11e7-a547-f6d178db6df1 | L2: Реализовано | M2: 59599dd2-c972-11ed-8109-00155d000d00 | N2: 7c3ca0c6-c6ed-11e3-8894-0015171241a5 | O2: 6c972905-f36a-11e8-9fe3-d000e1470f5d | P2: bf6910b9-e175-11ef-ab6a-0cc47af964e9 | Q2: d5bcc2ca-e174-11ef-ab6a-0cc47af964e9 | R2: 609d494f-b566-11e7-a547-f6d178db6df1 | S2: 008da890-d0f0-11f0-99b9-00155dde6a00 | T2: лист | U2: м2 | V2: fa6fadf3-b578-11e7-a547-f6d178db6df1 | W2: Склад упаковки готовой продукции (ЗСП) | X2: 2 | Y2: 32 116,00 | Z2: 9.569 | AA2: 0.072 | AB2: Слопласт | AD2: 5 352,67 | AE2: 16 058,00 | AF2: ГК | AG2: f38645b5-1d2d-11f1-99bb-00155dde6a00 | AH2: e1cib/data/Документ.РеализацияТоваровУслуг?ref=99b900155dde6a0011f0d4e2e5b05548 | AI2: e53ee5f8-d0f0-11f0-99b9-00155dde6a00008da890-d0f0-11f0-99b9-00155dde6a00 | AJ2: УП-00114496
A3: ERP | B3: 46015.413 | C3: 4dbe3103-e096-11f0-99b9-00155dde6a00 | D3: Реализация товаров и услуг ЗСУП-005234 от 24.12.2025 10:01:09 | E3: ЗСУП-005234 | F3: 46015.417 | G3: 1 | H3: 0 | I3: Реализация | J3: null | K3: 9e38a44e-b7d0-11e7-a547-f6d178db6df1 | L3: Реализовано | M3: 59599dd2-c972-11ed-8109-00155d000d00 | N3: 7c3ca0c6-c6ed-11e3-8894-0015171241a5 | O3: 6c972905-f36a-11e8-9fe3-d000e1470f5d | P3: bf6910b9-e175-11ef-ab6a-0cc47af964e9 | Q3: d5bcc2ca-e174-11ef-ab6a-0cc47af964e9 | R3: 609d494f-b566-11e7-a547-f6d178db6df1 | S3: 008da890-d0f0-11f0-99b9-00155dde6a00 | T3: лист | U3: м2 | V3: fa6fadf3-b578-11e7-a547-f6d178db6df1 | W3: Склад упаковки готовой продукции (ЗСП) | X3: 6 | Y3: 96 348,00 | Z3: 28.708 | AA3: 0.215 | AB3: Слопласт | AD3: 16 058,00 | AE3: 16 058,00 | AF3: ГК | AG3: 80941762-16e0-11f1-99b9-00155dde6a00 | AH3: e1cib/data/Документ.РеализацияТоваровУслуг?ref=99b900155dde6a0011f0e0964dbe3103 | AI3: 7ec0f5a3-dbf2-11f0-99b9-00155dde6a00008da890-d0f0-11f0-99b9-00155dde6a00 | AJ3: УП-00114496
A4: ERP | B4: 46001.532 | C4: ad716318-d5a6-11f0-99b9-00155dde6a00 | D4: Реализация товаров и услуг ЗСУП-004988 от 10.12.2025 12:00:30 | E4: ЗСУП-004988 | F4: 46001.5 | G4: 1 | H4: 0 | I4: Реализация | J4: null | K4: 9e38a44e-b7d0-11e7-a547-f6d178db6df1 | L4: Реализовано | M4: 59599dd2-c972-11ed-8109-00155d000d00 | N4: 7c3ca0c6-c6ed-11e3-8894-0015171241a5 | O4: 6c972905-f36a-11e8-9fe3-d000e1470f5d | P4: bf6910b9-e175-11ef-ab6a-0cc47af964e9 | Q4: d5bcc2ca-e174-11ef-ab6a-0cc47af964e9 | R4: 609d494f-b566-11e7-a547-f6d178db6df1 | S4: 008da890-d0f0-11f0-99b9-00155dde6a00 | T4: лист | U4: м2 | V4: fa6fadf3-b578-11e7-a547-f6d178db6df1 | W4: Склад упаковки готовой продукции (ЗСП) | X4: 1 | Y4: 16 058,00 | Z4: 4.785 | AA4: 0.036 | AB4: Слопласт | AD4: 2 676,33 | AE4: 16 058,00 | AF4: ГК | AG4: 80941762-16e0-11f1-99b9-00155dde6a00 | AH4: e1cib/data/Документ.РеализацияТоваровУслуг?ref=99b900155dde6a0011f0d5a6ad716318 | AI4: e53ee5f8-d0f0-11f0-99b9-00155dde6a00008da890-d0f0-11f0-99b9-00155dde6a00 | AJ4: УП-00114496
A5: ERP | B5: 45999.843 | C5: 03186bd9-114e-11f0-ab6a-0cc47af964e9 | D5: Реализация товаров и услуг ЗСУП-001468 от 04.04.2025 15:12:01 | E5: ЗСУП-001468 | F5: 45751.633 | G5: 1 | H5: 0 | I5: Реализация | J5: null | K5: 9e38a44e-b7d0-11e7-a547-f6d178db6df1 | L5: Реализовано | M5: 59599dd2-c972-11ed-8109-00155d000d00 | N5: fb9d6cbe-e968-11e7-80e4-00155d000d00 | O5: f6cbecfd-f367-11e8-9fe3-d000e1470f5d | P5: 6abd010e-f3bc-11e8-9fe3-d000e1470f5d | Q5: c42f193e-01ce-11e9-ab3f-0cc47af964e9 | R5: 609d494f-b566-11e7-a547-f6d178db6df1 | S5: 000386a5-cb7d-11e7-80e3-00155d000d00 | T5: лист | U5: м2 | V5: f027a6ed-b812-11e7-a547-f6d178db6df1 | W5: Склад Москва | X5: 20 | Y5: 171 700,00 | Z5: 95.694 | AA5: 0.954 | AB5: Слопласт | AD5: 28 616,67 | AE5: 8 585,00 | AF5: Транспорт | AG5: 80941762-16e0-11f1-99b9-00155dde6a00 | AH5: e1cib/data/Документ.РеализацияТоваровУслуг?ref=ab6a0cc47af964e911f0114e03186bd9 | AI5: 6782ea25-0a2e-11f0-ab6a-0cc47af964e9000386a5-cb7d-11e7-80e3-00155d000d00 | AJ5: 00-00006192
A6: ERP | B6: 45999.843 | C6: 40e2e0e1-b4b7-11f0-99b8-00155dde6a00 | D6: Реализация товаров и услуг ЗСУП-004205 от 29.10.2025 14:06:02 | E6: ЗСУП-004205 | F6: 45959.588 | G6: 1 | H6: 0 | I6: Реализация | J6: null | K6: 9e38a44e-b7d0-11e7-a547-f6d178db6df1 | L6: Реализовано | M6: 59599dd2-c972-11ed-8109-00155d000d00 | N6: fb9d6cbe-e968-11e7-80e4-00155d000d00 | O6: f6cbecfd-f367-11e8-9fe3-d000e1470f5d | P6: 6abd010e-f3bc-11e8-9fe3-d000e1470f5d | Q6: 54206bf8-fefd-11ea-ab46-0cc47af964e9 | R6: 55c87efc-b566-11e7-a547-f6d178db6df1 | S6: 000386a5-cb7d-11e7-80e3-00155d000d00 | T6: лист | U6: м2 | V6: f027a6ed-b812-11e7-a547-f6d178db6df1 | W6: Склад Москва | X6: 12 | Y6: 103 020,00 | Z6: 57.416 | AA6: 0.572 | AB6: Слопласт | AC6: С4 | AD6: 17 170,00 | AE6: 8 585,00 | AF6: Транспорт | AG6: 80941762-16e0-11f1-99b9-00155dde6a00 | AH6: e1cib/data/Документ.РеализацияТоваровУслуг?ref=99b800155dde6a0011f0b4b740e2e0e1 | AI6: 327923bd-a060-11f0-99b7-00155dde6a00000386a5-cb7d-11e7-80e3-00155d000d00 | AJ6: 00-00006192
A7: ERP | B7: 46001.49 | C7: cc6c14e9-cc3a-11f0-99b9-00155dde6a00 | D7: Реализация товаров и услуг ЗСУП-004801 от 28.11.2025 12:15:43 | E7: ЗСУП-004801 | F7: 45989.511 | G7: 1 | H7: 0 | I7: Реализация | J7: null | K7: 9e38a44e-b7d0-11e7-a547-f6d178db6df1 | L7: Реализовано | M7: ca842095-b338-11e8-80e7-00155d000d00 | N7: f3ef402d-ff15-11ef-ab6a-0cc47af964e9 | O7: f3ef4054-ff15-11ef-ab6a-0cc47af964e9 | P7: 26361b55-9e9f-11f0-99b7-00155dde6a00 | Q7: 254335bb-a292-11f0-99b7-00155dde6a00 | R7: 609d494f-b566-11e7-a547-f6d178db6df1 | S7: 0a210693-8e39-11f0-99b7-00155dde6a00 | T7: лист | U7: м2 | V7: fa6fadf3-b578-11e7-a547-f6d178db6df1 | W7: Склад упаковки готовой продукции (ЗСП) | X7: 81 | Y7: 2 788 155,27 | Z7: 326.613 | AA7: 1.378 | AB7: Слопласт | AD7: 464 692,55 | AE7: 34 421,67 | AF7: Стройка | AG7: f38645b5-1d2d-11f1-99bb-00155dde6a00 | AH7: e1cib/data/Документ.РеализацияТоваровУслуг?ref=99b900155dde6a0011f0cc3acc6c14e9 | AI7: ed4df888-9e9f-11f0-99b7-00155dde6a000a210693-8e39-11f0-99b7-00155dde6a00 | AJ7: УП-00112269
A8: ERP | B8: 46001.448 | C8: 187f0979-cc37-11f0-99b9-00155dde6a00 | D8: Реализация товаров и услуг ЗСУП-004799 от 28.11.2025 11:49:10 | E8: ЗСУП-004799 | F8: 45989.492 | G8: 1 | H8: 0 | I8: Реализация | J8: null | K8: 9e38a44e-b7d0-11e7-a547-f6d178db6df1 | L8: Реализовано | M8: ca842095-b338-11e8-80e7-00155d000d00 | N8: f3ef402d-ff15-11ef-ab6a-0cc47af964e9 | O8: f3ef4054-ff15-11ef-ab6a-0cc47af964e9 | P8: 26361b55-9e9f-11f0-99b7-00155dde6a00 | Q8: 254335bb-a292-11f0-99b7-00155dde6a00 | R8: 609d494f-b566-11e7-a547-f6d178db6df1 | S8: 0a210693-8e39-11f0-99b7-00155dde6a00 | T8: лист | U8: м2 | V8: fa6fadf3-b578-11e7-a547-f6d178db6df1 | W8: Склад упаковки готовой продукции (ЗСП) | X8: 240 | Y8: 8 261 200,80 | Z8: 967.742 | AA8: 4.083 | AB8: Слопласт | AD8: 1 376 866,80 | AE8: 34 421,67 | AF8: Стройка | AG8: f38645b5-1d2d-11f1-99bb-00155dde6a00 | AH8: e1cib/data/Документ.РеализацияТоваровУслуг?ref=99b900155dde6a0011f0cc37187f0979 | AI8: ed4df888-9e9f-11f0-99b7-00155dde6a000a210693-8e39-11f0-99b7-00155dde6a00 | AJ8: УП-00112269
A9: ERP | B9: 46001.49 | C9: cc6c14e9-cc3a-11f0-99b9-00155dde6a00 | D9: Реализация товаров и услуг ЗСУП-004801 от 28.11.2025 12:15:43 | E9: ЗСУП-004801 | F9: 45989.511 | G9: 1 | H9: 0 | I9: Реализация | J9: null | K9: 9e38a44e-b7d0-11e7-a547-f6d178db6df1 | L9: Реализовано | M9: ca842095-b338-11e8-80e7-00155d000d00 | N9: f3ef402d-ff15-11ef-ab6a-0cc47af964e9 | O9: f3ef4054-ff15-11ef-ab6a-0cc47af964e9 | P9: 26361b55-9e9f-11f0-99b7-00155dde6a00 | Q9: 254335bb-a292-11f0-99b7-00155dde6a00 | R9: 609d494f-b566-11e7-a547-f6d178db6df1 | S9: 0a210693-8e39-11f0-99b7-00155dde6a00 | T9: лист | U9: м2 | V9: fa6fadf3-b578-11e7-a547-f6d178db6df1 | W9: Склад упаковки готовой продукции (ЗСП) | X9: 16 | Y9: 550 746,72 | Z9: 64.516 | AA9: 0.272 | AB9: Слопласт | AD9: 91 791,12 | AE9: 34 421,67 | AF9: Стройка | AG9: f38645b5-1d2d-11f1-99bb-00155dde6a00 | AH9: e1cib/data/Документ.РеализацияТоваровУслуг?ref=99b900155dde6a0011f0cc3acc6c14e9 | AI9: ed4df888-9e9f-11f0-99b7-00155dde6a000a210693-8e39-11f0-99b7-00155dde6a00 | AJ9: УП-00112269
A10: ERP | B10: 45999.843 | C10: ac6b068d-cf38-11ef-ab69-0cc47af964e9 | D10: Реализация товаров и услуг ЗСУП-000019 от 10.01.2025 12:52:59 | E10: ЗСУП-000019 | F10: 45667.537 | G10: 1 | H10: 0 | I10: Реализация | J10: null | K10: 9e38a44e-b7d0-11e7-a547-f6d178db6df1 | L10: Реализовано | M10: c500dad6-819e-11e7-80e2-00155d000d00 | N10: 78d73f12-f36a-11e8-9fe3-d000e1470f5d | O10: 78d73f13-f36a-11e8-9fe3-d000e1470f5d | P10: 132ad76f-5aaa-11ed-ab58-0cc47af964e9 | Q10: 8c0ae592-d13a-11ec-ab51-0cc47af964e9 | R10: 609d494f-b566-11e7-a547-f6d178db6df1 | S10: 194970a4-6577-11ed-ab59-0cc47af964e9 | T10: лист | U10: м2 | V10: fa6fadf3-b578-11e7-a547-f6d178db6df1 | W10: Склад упаковки готовой продукции (ЗСП) | X10: 139 | Y10: 205 859,00 | Z10: 560.484 | AA10: 47.295 | AB10: Слопласт | AD10: 34 309,83 | AE10: 1 481,00 | AF10: Мебель | AG10: 653048a2-1955-11f1-99bb-00155dde6a00 | AH10: e1cib/data/Документ.РеализацияТоваровУслуг?ref=ab690cc47af964e911efcf38ac6b068d | AI10: 9ed26bb3-9dca-11ef-ab68-0cc47af964e9194970a4-6577-11ed-ab59-0cc47af964e9 | AJ10: УП-00080436
A11: ERP | B11: 45999.843 | C11: d6f2c30f-d317-11ef-ab69-0cc47af964e9 | D11: Реализация товаров и услуг ЗСУП-000092 от 15.01.2025 11:08:05 | E11: ЗСУП-000092 | F11: 45672.464 | G11: 1 | H11: 0 | I11: Реализация | J11: null | K11: 9e38a44e-b7d0-11e7-a547-f6d178db6df1 | L11: Реализовано | M11: c500dad6-819e-11e7-80e2-00155d000d00 | N11: 78d73f12-f36a-11e8-9fe3-d000e1470f5d | O11: 78d73f13-f36a-11e8-9fe3-d000e1470f5d | P11: 132ad76f-5aaa-11ed-ab58-0cc47af964e9 | Q11: 8c0ae592-d13a-11ec-ab51-0cc47af964e9 | R11: 609d494f-b566-11e7-a547-f6d178db6df1 | S11: 194970a4-6577-11ed-ab59-0cc47af964e9 | T11: лист | U11: м2 | V11: fa6fadf3-b578-11e7-a547-f6d178db6df1 | W11: Склад упаковки готовой продукции (ЗСП) | X11: 47 | Y11: 69 607,00 | Z11: 189.516 | AA11: 15.992 | AB11: Слопласт | AD11: 11 601,17 | AE11: 1 481,00 | AF11: Мебель | AG11: 653048a2-1955-11f1-99bb-00155dde6a00 | AH11: e1cib/data/Документ.РеализацияТоваровУслуг?ref=ab690cc47af964e911efd317d6f2c30f | AI11: f2d22a58-bded-11ef-ab69-0cc47af964e9194970a4-6577-11ed-ab59-0cc47af964e9 | AJ11: УП-00080436
A12: ERP | B12: 45999.843 | C12: 5528c09f-da2f-11ef-ab69-0cc47af964e9 | D12: Реализация товаров и услуг ЗСУП-000322 от 24.01.2025 11:43:52 | E12: ЗСУП-000322 | F12: 45681.489 | G12: 1 | H12: 0 | I12: Реализация | J12: null | K12: 9e38a44e-b7d0-11e7-a547-f6d178db6df1 | L12: Реализовано | M12: bafef812-be80-11ee-ab64-0cc47af964e9 | N12: 3fa69b08-b7a5-11e2-ae63-0015171241a4 | O12: 35ad1025-f36b-11e8-9fe3-d000e1470f5d | P12: 98eb8223-4986-11ef-ab64-0cc47af964e9 | Q12: 52094fa9-769a-11eb-ab4c-0cc47af964e9 | R12: 609d494f-b566-11e7-a547-f6d178db6df1 | S12: 194970a4-6577-11ed-ab59-0cc47af964e9 | T12: лист | U12: м2 | V12: fa6fadf3-b578-11e7-a547-f6d178db6df1 | W12: Склад упаковки готовой продукции (ЗСП) | X12: 108 | Y12: 159 948,00 | Z12: 435.484 | AA12: 36.747 | AB12: Слопласт | AD12: 26 658,00 | AE12: 1 481,00 | AF12: Мебель | AG12: 653048a2-1955-11f1-99bb-00155dde6a00 | AH12: e1cib/data/Документ.РеализацияТоваровУслуг?ref=ab690cc47af964e911efda2f5528c09f | AI12: aa40444f-b08f-11ef-ab69-0cc47af964e9194970a4-6577-11ed-ab59-0cc47af964e9 | AJ12: УП-00080436
